Workbook

Sheet Home
L14: Dados Históricos / Historical Data
M18: INDICADORES / KPI | R18: EBITDA | W18: BS CONSOLIDADO
M24: DRE /INCOME STATEMENT | R24: BALANÇO / BALANCE SHEET | W24: P&l CONSOLIDADO
R29: RECEITA / REVENUE

Sheet Indicadores | KPI
B1: Principais Indicadores | C1: Main KPIs
D2: 1T15 | E2: 2T15 | F2: 3T15 | G2: 4T15 | H2: 2015 | I2: 1T16 | J2: 2T16 | K2: 3T16 | L2: 4T16 | M2: 2016 | N2: 1T17 | O2: 2T17 | P2: 3T17 | Q2: 4T17 | R2: 2017 | S2: 1T18 | T2: 2T18 | U2: 3T18 | V2: 4T18 | W2: 2018 | X2: 1T19 | Y2: 2T19 | Z2: 3T19 | AA2: 4T19 | AB2: 2019 | AC2: 1T20 | AD2: 2T20 | AE2: 3T20 | AF2: 4T20 | AG2: 2020 | AH2: 1T21 | AI2: 2T21 | AJ2: 3T21 | AK2: 4T21 | AL2: 2021 | AM2: 1T22 | AN2: 2T22 | AO2: 3T22 | AP2: 4T22 | AQ2: 2022 | AR2: 1T23 | AS2: 2T23 | AT2: 3T23 | AU2: 4T23 | AV2: 2023 | AW2: 1T24 | AX2: 2T24 | AY2: 3T24 | AZ2: 4T24 | BA2: 2024 | BB2: 1T25 | BC2: 2T25 | BD2: 3T25 | BE2: 4T25 | BF2: 2025 | BG2: 1T26 | BH2: 2T26
B3: Receita Líquida | C3: Net Revenue | D3: 1555436.2 | E3: 1665054.9 | F3: 1790312.4 | G3: 1835652.6 | H3: =SUM(D3:G3) -> 6846456.1 | I3: 1782357 | J3: 1760127.5 | K3: 1595510.5 | L3: 1678459 | M3: =SUM(I3:L3) -> 6816454 | N3: 1699036 | O3: 1901808.9 | P3: 1932450.6 | Q3: 1954644 | R3: =SUM(N3:Q3) -> 7487939.5 | S3: 2143752 | T3: 2399485 | U3: 2617310 | V3: 2455752 | W3: =SUM(S3:V3) -> 9616299 | X3: 2468119 | Y3: 2667331 | Z3: 2542311 | AA3: 2338634 | AB3: =SUM(X3:AA3) -> 10016395 | AC3: 2224560 | AD3: 1171844 | AE3: 2514756 | AF3: 2849408 | AG3: =SUM(AC3:AF3) -> 8760568 | AH3: 3133096 | AI3: 3183882.4 | AJ3: 3583978 | AK3: 3787410 | AL3: =SUM(AH3:AK3) -> 13688366 | AM3: 4277191 | AN3: 4192384 | AO3: 4318339 | AP3: 4159955 | AQ3: =SUM(AM3:AP3) -> 16947869 | AR3: 3998153 | AS3: 3801203 | AT3: 3672363 | AU3: 3483501 | AV3: =SUM(AR3:AU3) -> 14955220 | AW3: 3595766 | AX3: 3844568 | AY3: 3982373 | AZ3: 3909106 | BA3: =SUM(AW3:AZ3) -> 15331813 | BB3: 3938050 | BC3: 4106968 | BD3: 3802399 | BE3: 3519120 | BF3: 15366537 | BG3: ='DRE- Income Statement'!BF5 -> 3807333 | BH3: ='DRE- Income Statement'!BG5 -> 4012470
B4: Lucro Bruto | C4: Gross Profit | D4: 190482.77 | E4: 218305.08 | F4: 251434.1 | G4: 231806.17 | H4: 892028.13 | I4: 226582.07 | J4: 256257 | K4: 234387.25 | L4: 254561.61 | M4: 971787.94 | N4: 242779.1 | O4: 298208.28 | P4: 318429.58 | Q4: 295560.72 | R4: 1154977.7 | S4: 294852.89 | T4: 337791.45 | U4: 379382.1 | V4: 306249.02 | W4: 1318275.5 | X4: 298308.43 | Y4: 336575.05 | Z4: 322690.28 | AA4: 227643.2 | AB4: 1185217 | AC4: 184356.3 | AD4: -136336.3 | AE4: 255675.35 | AF4: 261618 | AG4: 565313.35 | AH4: 409716 | AI4: 420717.52 | AJ4: 495590.7 | AK4: 378098 | AL4: 1704122.2 | AM4: 611000.02 | AN4: 534650.23 | AO4: 338956.14 | AP4: 324035.51 | AQ4: 1808641.9 | AR4: 341086.1 | AS4: 424728.07 | AT4: 362191.08 | AU4: 380239.27 | AV4: 1508244.5 | AW4: 384128.76 | AX4: 476556 | AY4: 477737 | AZ4: 483011 | BA4: 1338421.8 | BB4: 443732 | BC4: 534617 | BD4: 460315 | BE4: 412108 | BF4: 1850772 | BG4: ='DRE- Income Statement'!BF11 -> 441538 | BH4: ='DRE- Income Statement'!BG11 -> 485543
B5: Lucro (Prejuízo) Líquido | C5: Net Income (Loss) | D5: -6678.3554 | E5: 70241.068 | F5: 2433.691 | G5: -16630.655 | H5: 449602.13 | I5: 6982.0714 | J5: -7192.2873 | K5: 4892.54 | L5: 16847.611 | M5: =SUM(I5:L5) -> 21529.935 | N5: -1250.3134 | O5: 24570.316 | P5: -28721.421 | Q5: 11804.725 | R5: =SUM(N5:Q5) -> 6403.3058 | S5: -12966.111 | T5: 44134.451 | U5: 93479.1 | V5: 76677.02 | W5: =SUM(S5:V5) -> 201324.46 | X5: 63096.433 | Y5: 110390.05 | Z5: 124838.28 | AA5: 39109.203 | AB5: =SUM(X5:AA5) -> 337433.97 | AC5: 9150.2979 | AD5: -352353.3 | AE5: -18876.646 | AF5: -129700 | AG5: =SUM(AC5:AF5) -> -491779.65 | AH5: 51502 | AI5: 214786.52 | AJ5: 177015.7 | AK5: 93916 | AL5: =SUM(AH5:AK5) -> 537220.21 | AM5: 160206.02 | AN5: 190485.23 | AO5: 69387.722 | AP5: -141146.49 | AQ5: =SUM(AM5:AP5) -> 278932.48 | AR5: -16340.903 | AS5: 59360.073 | AT5: -4784.9222 | AU5: -7501.7261 | AV5: =SUM(AR5:AU5) -> 30732.522 | AW5: 50257 | AX5: 36925 | AY5: 109172 | AZ5: 68366 | BA5: =SUM(AW5:AZ5) -> 264720 | BB5: 10892 | BC5: 86822 | BD5: 35067 | BE5: -34398 | BF5: 98383 | BG5: ='DRE- Income Statement'!BF32 -> 3920 | BH5: ='DRE- Income Statement'!BG32 -> 86869
B6: EBITDA | C6: EBITDA | D6: 139833.52 | E6: 242501.9 | F6: 204669.95 | G6: 164061.6 | H6: =SUM(D6:G6) -> 751066.97 | I6: 236295.42 | J6: 179570.95 | K6: 191109.14 | L6: 189249.51 | M6: =SUM(I6:L6) -> 796225.02 | N6: 185393.84 | O6: 194139.02 | P6: 220254.57 | Q6: 198765.91 | R6: =SUM(N6:Q6) -> 798553.34 | S6: 227112.85 | T6: 275408.5 | U6: 311999.73 | V6: 242554.66 | W6: =SUM(S6:V6) -> 1057075.7 | X6: 242587.39 | Y6: 304247.27 | Z6: 333779.69 | AA6: 215195.55 | AB6: =SUM(X6:AA6) -> 1095809.9 | AC6: 204967.46 | AD6: -199515.39 | AE6: 207676.01 | AF6: 159011.44 | AG6: =SUM(AC6:AF6) -> 372139.51 | AH6: 367938.26 | AI6: 592729.23 | AJ6: 489861.86 | AK6: 390803.28 | AL6: =SUM(AH6:AK6) -> 1841332.6 | AM6: 548151.67 | AN6: 534572.73 | AO6: 362701.61 | AP6: 291488.72 | AQ6: =SUM(AM6:AP6) -> 1736914.7 | AR6: 286760.45 | AS6: 363406.6 | AT6: 313322.08 | AU6: 289375.03 | AV6: =SUM(AR6:AU6) -> 1252864.2 | AW6: 316641.76 | AX6: 388931 | AY6: 440235 | AZ6: 378263 | BA6: =SUM(AW6:AZ6) -> 1524070.8 | BB6: 354362 | BC6: 450478 | BD6: 360435 | BE6: 328178 | BF6: 1493453 | BG6: 357046 | BH6: 417527
B7: Alavancagem | C7: Leverage | D7: =2546/637 -> 3.9968603 | E7: =2424/731 -> 3.3160055 | F7: =2728/768 -> 3.5520833 | G7: =2676/751 -> 3.563249 | H7: =2676/751 -> 3.563249 | I7: =2794/847 -> 3.2987013 | J7: =2578/784 -> 3.2882653 | K7: =2767/771 -> 3.5888457 | L7: =2628/796 -> 3.3015075 | M7: =2628/796 -> 3.3015075 | N7: =2128/745 -> 2.8563758 | O7: =2247/759 -> 2.9604743 | P7: =2282/789 -> 2.8922687 | Q7: =2299/798 -> 2.8809524 | R7: =2299/798 -> 2.8809524 | S7: =2230/840 -> 2.6547619 | T7: =2530/921 -> 2.7470141 | U7: =2602/1013 -> 2.5686081 | V7: =2326/1057 -> 2.2005676 | W7: =2326/1057 -> 2.2005676 | X7: =2727/1072 -> 2.5438433 | Y7: =2640/1101 -> 2.3978202 | Z7: =2668/1123 -> 2.3757792 | AA7: =2415/1095 -> 2.2054795 | AB7: =2415/1095 -> 2.2054795 | AC7: =3166/1058 -> 2.9924386 | AD7: =3636/554 -> 6.5631769 | AE7: =3738/428 -> 8.7336449 | AF7: 9.45 | AG7: 9.45 | AH7: =4057/535 -> 7.5831776 | AI7: =3981/1327 -> 3 | AJ7: =4522/1609 -> 2.8104413 | AK7: =4299/1841 -> 2.3351439 | AL7: =4299/1841 -> 2.3351439 | AM7: 2.06 | AN7: 2.21 | AO7: 2.27 | AP7: 2.26 | AQ7: 2.26 | AR7: 2.77 | AS7: 2.72 | AT7: 2.85 | AU7: 2.93 | AV7: 2.93 | AW7: 2.95 | AX7: 2.97 | AY7: =2.59 -> 2.59 | AZ7: 2.39 | BA7: 2.39 | BB7: 2.34 | BC7: 2.34 | BD7: 2.38 | BE7: 2.55 | BF7: 2.65 | BG7: 2.49 | BH7: 2.52
B8: Liquidez | C8: Liquidity Ratio | AI8: 0.75 | AJ8: 0.54 | AK8: 0.73 | AL8: 0.73 | AM8: 0.669 | AN8: 1.48 | AO8: 1.66 | AP8: 2.67 | AQ8: 2.67 | AR8: 1.54 | AS8: 1.63 | AT8: 2 | AU8: 2.12

Sheet DRE- Income Statement
A3: Consolidado | B3: Consolidated
A4: DRE - R$ mil | B4: I.S - R$ thousand | C4: 1T15 | D4: 2T15 | E4: 3T15 | F4: 4T15 | G4: 2015 | H4: 1T16 | I4: 2T16 | J4: 3T16 | K4: 4T16 | L4: 2016 | M4: 1T17 | N4: 2T17 | O4: 3T17 | P4: 4T17 | Q4: 2017 | R4: 1T18 | S4: 2T18 | T4: 3T18 | U4: 4T18 | V4: 2018 | W4: 1T19 | X4: 2T19 | Y4: 3T19 | Z4: 4T19 | AA4: 2019 | AB4: 1T20 | AC4: 2T20 | AD4: 3T20 | AE4: 4T20 | AF4: 2020 | AG4: 1T21 | AH4: 2T21 | AI4: 3T21 | AJ4: 4T21 | AK4: 2021 | AL4: 1T22 | AM4: 2T22 | AN4: 3T22 | AO4: 4T22 | AP4: 2022 | AQ4: 1T23 | AR4: 2T23 | AS4: 3T23 | AT4: 4T23 | AU4: 2023 | AV4: 1T24 | AW4: 2T24 | AX4: 3T24 | AY4: 4T24 | AZ4: 2024 | BA4: 1T25 | BB4: 2T25 | BC4: 3T25 | BD4: 4T25 | BE4: 2025 | BF4: 1T26 | BG4: 2T26
A5: Receita Operacional Líquida | B5: Net Operating Revenue | C5: 1555436.2 | D5: 1665054.9 | E5: 1790312.4 | F5: 1835652.6 | G5: =SUM(C5:F5) -> 6846456.1 | H5: 1782357 | I5: 1760127.5 | J5: 1595510.5 | K5: 1678459 | L5: =SUM(H5:K5) -> 6816454 | M5: 1699036 | N5: 1901808.9 | O5: 1932450.6 | P5: 1954644 | Q5: =SUM(M5:P5) -> 7487939.5 | R5: 2143752 | S5: 2399485 | T5: 2617310 | U5: 2455752 | V5: =SUM(R5:U5) -> 9616299 | W5: 2468119 | X5: 2667331 | Y5: 2542311 | Z5: 2338634 | AA5: =SUM(W5:Z5) -> 10016395 | AB5: 2224560 | AC5: 1171844 | AD5: 2514756 | AE5: 2849408 | AF5: =SUM(AB5:AE5) -> 8760568 | AG5: 3133096 | AH5: 3183882.4 | AI5: 3583978 | AJ5: 3787410 | AK5: =SUM(AG5:AJ5) -> 13688366 | AL5: 4277191 | AM5: 4192384 | AN5: 4318339 | AO5: 4159955 | AP5: =SUM(AL5:AO5) -> 16947869 | AQ5: 3998153 | AR5: 3801203 | AS5: 3672363 | AT5: 3483501 | AU5: =SUM(AQ5:AT5) -> 14955220 | AV5: 3595766 | AW5: 3844568 | AX5: 3982373 | AY5: ='P&L - Consolidado'!O3 -> 3909106 | AZ5: =SUM(AV5:AY5) -> 15331813 | BA5: ='P&L - Consolidado'!M3 -> 3938050 | BB5: ='P&L - Consolidado'!L3 -> 4106968 | BC5: ='P&L - Consolidado'!J3 -> 3802399 | BD5: ='P&L - Consolidado'!H3 -> 3519120 | BE5: =SUM(BA5:BD5) -> 15366537 | BF5: ='P&L - Consolidado'!F3 -> 3807333 | BG5: ='P&L - Consolidado'!E3 -> 4012470
A6: Custo dos Produtos Vendidos | B6: Cost of Goods Sold
A7: Matéria Prima | B7: Raw Material | C7: -821160.48 | D7: -886285.98 | E7: -929515.74 | F7: -949040.8 | G7: =SUM(C7:F7) -> -3586003 | H7: -903779.55 | I7: -876308.16 | J7: -781894.94 | K7: -828761.32 | L7: =SUM(H7:K7) -> -3390744 | M7: -875313.05 | N7: -988407.68 | O7: -994268.31 | P7: -1011167.5 | Q7: =SUM(M7:P7) -> -3869156.5 | R7: -1117554.5 | S7: -1271329.4 | T7: -1387085.1 | U7: -1275104.6 | V7: =SUM(R7:U7) -> -5051073.6 | W7: -1307644.1 | X7: -1436650.4 | Y7: -1313964.6 | Z7: -1205334.8 | AA7: =SUM(W7:Z7) -> -5263593.8 | AB7: -1170979.1 | AC7: -616023.5 | AD7: -1319747.5 | AE7: -1433279.3 | AF7: =SUM(AB7:AE7) -> -4540029.5 | AG7: -1576803.5 | AH7: -1629031.4 | AI7: -1921053.8 | AJ7: -2123870.9 | AK7: =SUM(AG7:AJ7) -> -7250759.5 | AL7: -2447332.4 | AM7: -2458703.8 | AN7: -2672667.8 | AO7: -2513181.9 | AP7: =SUM(AL7:AO7) -> -10091886 | AQ7: -2284634.4 | AR7: -2090441.8 | AS7: -2024418.9 | AT7: -1856329.6 | AU7: =SUM(AQ7:AT7) -> -8255824.8 | AV7: -1899035.4 | AW7: -1999447.2 | AX7: -2071783.4 | AY7: -1983810 | AZ7: =SUM(AV7:AY7) -> -7954076 | BA7: -1983429.8 | BB7: -2044159.2 | BC7: -2044159.2 | BD7: -1758035 | BE7: =SUM(BA7:BD7) -> -7829783.1 | BF7: -1924363 | BG7: -2042467.4
A8: Mão de Obra | B8: Labor | C8: -272878.38 | D8: -271677.32 | E8: -277797.7 | F8: -280736.91 | G8: =SUM(C8:F8) -> -1103090.3 | H8: -306898.46 | I8: -296137.01 | J8: -280055.85 | K8: -279714.24 | L8: =SUM(H8:K8) -> -1162805.6 | M8: -277041.8 | N8: -307368.45 | O8: -304900.2 | P8: -317091.1 | Q8: =SUM(M8:P8) -> -1206401.6 | R8: -341144.09 | S8: -377040.6 | T8: -389739.81 | U8: -401963.51 | V8: =SUM(R8:U8) -> -1509888 | W8: -412480.18 | X8: -425120.34 | Y8: -418805.19 | Z8: -421183.58 | AA8: =SUM(W8:Z8) -> -1677589.3 | AB8: -433727.73 | AC8: -311523.16 | AD8: -431134.19 | AE8: -482475.74 | AF8: =SUM(AB8:AE8) -> -1658860.8 | AG8: -521264.26 | AH8: -514603.15 | AI8: -517129.21 | AJ8: -544846.86 | AK8: =SUM(AG8:AJ8) -> -2097843.5 | AL8: -541564.5 | AM8: -518196.98 | AN8: -554266.42 | AO8: -563628.02 | AP8: =SUM(AL8:AO8) -> -2177655.9 | AQ8: -602659.22 | AR8: -575557.96 | AS8: -579825.62 | AT8: -555444.18 | AU8: =SUM(AQ8:AT8) -> -2313487 | AV8: -623433.1 | AW8: -651126.45 | AX8: -675676.32 | AY8: -657013 | AZ8: =SUM(AV8:AY8) -> -2607248.9 | BA8: -719033.4 | BB8: -740674.22 | BC8: -740674.22 | BD8: -652668 | BE8: =SUM(BA8:BD8) -> -2853049.8 | BF8: -713884 | BG8: -730470.25
A9: Outros | B9: Others | C9: -270914.57 | D9: -288786.54 | E9: -331564.89 | F9: -374068.69 | G9: =SUM(C9:F9) -> -1265334.7 | H9: -345096.92 | I9: -331425.29 | J9: -299172.5 | K9: -315421.83 | L9: =SUM(H9:K9) -> -1291116.5 | M9: -303902.06 | N9: -307824.47 | O9: -314852.54 | P9: -330824.7 | Q9: =SUM(M9:P9) -> -1257403.8 | R9: -390200.54 | S9: -413323.53 | T9: -461101.36 | U9: -472434.92 | V9: =SUM(R9:U9) -> -1737060.4 | W9: -449686.27 | X9: -468985.24 | Y9: -486850.93 | Z9: -484472.46 | AA9: =SUM(W9:Z9) -> -1889994.9 | AB9: -435496.82 | AC9: -380633.63 | AD9: -508198.94 | AE9: -672034.6 | AF9: =SUM(AB9:AE9) -> -1996364 | AG9: -625312.07 | AH9: -619530.42 | AI9: -650204.34 | AJ9: -740594.4 | AK9: =SUM(AG9:AJ9) -> -2635641.2 | AL9: -677294.1 | AM9: -680832.94 | AN9: -752448.63 | AO9: -759109.56 | AP9: =SUM(AL9:AO9) -> -2869685.2 | AQ9: -769773.25 | AR9: -710475.13 | AS9: -705927.38 | AT9: -691487.95 | AU9: =SUM(AQ9:AT9) -> -2877663.7 | AV9: -689168.73 | AW9: -717438.43 | AX9: -757176.19 | AY9: -785272 | AZ9: =SUM(AV9:AY9) -> -2949055.3 | BA9: -791855.07 | BB9: -787517.88 | BC9: -787517.88 | BD9: -696309 | BE9: =SUM(BA9:BD9) -> -3063199.8 | BF9: -727549 | BG9: -753989.35
C10: =SUM(C7:C9) -> -1364953.4 | D10: =SUM(D7:D9) -> -1446749.8 | E10: =SUM(E7:E9) -> -1538878.3 | F10: =SUM(F7:F9) -> -1603846.4 | G10: =SUM(C10:F10) -> -5954428 | H10: =SUM(H7:H9) -> -1555774.9 | I10: =SUM(I7:I9) -> -1503870.5 | J10: =SUM(J7:J9) -> -1361123.3 | K10: =SUM(K7:K9) -> -1423897.4 | L10: =SUM(H10:K10) -> -5844666.1 | M10: =SUM(M7:M9) -> -1456256.9 | N10: =SUM(N7:N9) -> -1603600.6 | O10: =SUM(O7:O9) -> -1614021 | P10: =SUM(P7:P9) -> -1659083.3 | Q10: =SUM(M10:P10) -> -6332961.8 | R10: =SUM(R7:R9) -> -1848899.1 | S10: =SUM(S7:S9) -> -2061693.5 | T10: =SUM(T7:T9) -> -2237926.3 | U10: =SUM(U7:U9) -> -2149503 | V10: =SUM(R10:U10) -> -8298021.9 | W10: =SUM(W7:W9) -> -2169810.6 | X10: =SUM(X7:X9) -> -2330755.9 | Y10: =SUM(Y7:Y9) -> -2219620.7 | Z10: -2110990.8 | AA10: =SUM(W10:Z10) -> -8831178 | AB10: -2040203.7 | AC10: =SUM(AC7:AC9) -> -1308180.3 | AD10: =SUM(AD7:AD9) -> -2259080.6 | AE10: -2587790 | AF10: =SUM(AB10:AE10) -> -8195254.6 | AG10: -2723380 | AH10: -2763164.9 | AI10: =SUM(AI7:AI9) -> -3088387.3 | AJ10: -3409312 | AK10: =SUM(AG10:AJ10) -> -11984244 | AL10: =SUM(AL7:AL9) -> -3666191 | AM10: =SUM(AM7:AM9) -> -3657733.8 | AN10: =SUM(AN7:AN9) -> -3979382.9 | AO10: =SUM(AO7:AO9) -> -3835919.5 | AP10: =SUM(AL10:AO10) -> -15139227 | AQ10: =SUM(AQ7:AQ9) -> -3657066.9 | AR10: =SUM(AR7:AR9) -> -3376474.9 | AS10: =SUM(AS7:AS9) -> -3310171.9 | AT10: =SUM(AT7:AT9) -> -3103261.7 | AU10: =SUM(AQ10:AT10) -> -13446975 | AV10: =SUM(AV7:AV9) -> -3211637.2 | AW10: -3368012 | AX10: -3504636 | AY10: ='P&L - Consolidado'!O4 -> -3426095 | AZ10: =SUM(AV10:AY10) -> -13510380 | BA10: ='P&L - Consolidado'!M4 -> -3494318 | BB10: ='P&L - Consolidado'!L4 -> -3572351 | BC10: ='P&L - Consolidado'!J4 -> -3342084 | BD10: ='P&L - Consolidado'!H4 -> -3107012 | BE10: =SUM(BA10:BD10) -> -13515765 | BF10: ='P&L - Consolidado'!F4 -> -3365795 | BG10: ='P&L - Consolidado'!E4 -> -3526927
A11: Lucro (Prejuízo) Bruto | B11: Gross Profit | C11: =C5+C10 -> 190482.77 | D11: =D5+D10 -> 218305.08 | E11: =E5+E10 -> 251434.1 | F11: =F5+F10 -> 231806.17 | G11: =SUM(C11:F11) -> 892028.13 | H11: =H5+H10 -> 226582.07 | I11: =I5+I10 -> 256257 | J11: =J5+J10 -> 234387.25 | K11: =K5+K10 -> 254561.61 | L11: =SUM(H11:K11) -> 971787.94 | M11: =M5+M10 -> 242779.1 | N11: =N5+N10 -> 298208.28 | O11: =O5+O10 -> 318429.58 | P11: =P5+P10 -> 295560.72 | Q11: =SUM(M11:P11) -> 1154977.7 | R11: =R5+R10 -> 294852.89 | S11: =S5+S10 -> 337791.45 | T11: 379382.1 | U11: =U5+U10 -> 306249.02 | V11: =SUM(R11:U11) -> 1318275.5 | W11: =W5+W10 -> 298308.43 | X11: =X5+X10 -> 336575.05 | Y11: =Y5+Y10 -> 322690.28 | Z11: =Z10+Z5 -> 227643.2 | AA11: =SUM(W11:Z11) -> 1185217 | AB11: 184356.3 | AC11: =AC5+AC10 -> -136336.3 | AD11: =AD5+AD10 -> 255675.35 | AE11: 261618 | AF11: =SUM(AB11:AE11) -> 565313.35 | AG11: 409716 | AH11: =AH10+AH5 -> 420717.52 | AI11: =AI10+AI5 -> 495590.7 | AJ11: =AJ10+AJ5 -> 378098 | AK11: =SUM(AG11:AJ11) -> 1704122.2 | AL11: =AL10+AL5 -> 611000.02 | AM11: =AM10+AM5 -> 534650.23 | AN11: =AN10+AN5 -> 338956.14 | AO11: =AO10+AO5 -> 324035.51 | AP11: =SUM(AL11:AO11) -> 1808641.9 | AQ11: =AQ10+AQ5 -> 341086.1 | AR11: =AR10+AR5 -> 424728.07 | AS11: =AS10+AS5 -> 362191.08 | AT11: =AT10+AT5 -> 380239.27 | AU11: =SUM(AQ11:AT11) -> 1508244.5 | AV11: =AV10+AV5 -> 384128.76 | AW11: 476556 | AX11: =AX5+AX10 -> 477737 | AY11: =AY5+AY10 -> 483011 | AZ11: =SUM(AV11:AY11) -> 1821432.8 | BA11: =BA10+BA5 -> 443732 | BB11: =BB10+BB5 -> 534617 | BC11: =BC10+BC5 -> 460315 | BD11: =BD10+BD5 -> 412108 | BE11: =SUM(BA11:BD11) -> 1850772 | BF11: =BF10+BF5 -> 441538 | BG11: =BG10+BG5 -> 485543
C12: =C11/C5 -> 0.12246261 | D12: =D11/D5 -> 0.13110984 | E12: =E11/E5 -> 0.14044147 | F12: =F11/F5 -> 0.12627998 | G12: =G11/G5 -> 0.13029049 | H12: =H11/H5 -> 0.12712497 | I12: =I11/I5 -> 0.14559003 | J12: =J11/J5 -> 0.14690423 | ... AA12: =AA11/AA5 -> 0.1183277 | AB12: 0.082873152 | AC12: =AC11/AC5 -> -0.11634339 | AD12: =AD11/AD5 -> 0.10167004 | AE12: =AE11/AE5 -> 0.091814861 | AF12: =AF11/AF5 -> 0.064529304 | AG12: 0.13077033 | AH12: =AH11/AH5 -> 0.13213978 | AI12: =AI11/AI5 -> 0.1382795 | AJ12: =AJ11/AJ5 -> 0.099830227 | AK12: =AK11/AK5 -> 0.1244942 | AL12: =AL11/AL5 -> 0.14285077 | AM12: =AM11/AM5 -> 0.12752893 | AN12: =AN11/AN5 -> 0.078492249 | AO12: =AO11/AO5 -> 0.077893994 | ... AV12: =AV11/AV5 -> 0.10682807 | AW12: 0.12395567 | AX12: =AX11/AX5 -> 0.1199629 | AY12: =AY11/AY5 -> 0.12356048 | AZ12: =AZ11/AZ5 -> 0.11880087 | BA12: =BA11/BA5 -> 0.1126781 | BB12: =BB11/BB5 -> 0.13017316 | BC12: =BC11/BC5 -> 0.1210591 | BD12: =BD11/BD5 -> 0.11710541 | BE12: =BE11/BE5 -> 0.12044171 | ... BG12: =BG11/BG5 -> 0.12100851
A13: Despesas Operacionais | B13: Operating Expenses
A14: Com vendas | B14: Selling expenses | C14: -31229 | D14: -35395 | E14: -39589 | F14: -49347 | G14: =SUM(C14:F14) -> -155560 | H14: -38745 | I14: -36594 | J14: -40025 | K14: -35567 | L14: =SUM(H14:K14) -> -150931 | M14: -35552 | N14: -42283 | O14: -42465 | P14: -41857 | Q14: =SUM(M14:P14) -> -162157 | R14: -9098 | S14: -10382 | T14: -17172 | U14: -38707 | V14: =SUM(R14:U14) -> -75359 | W14: -13873 | X14: -9142 | Y14: -17453 | Z14: -13310 | AA14: =SUM(W14:Z14) -> -53778 | AB14: -13258 | AC14: -13579 | AD14: -11754 | AE14: -23221 | AF14: =SUM(AB14:AE14) -> -61812 | AG14: -22412 | AH14: -12457 | AI14: -19100 | AJ14: -24517 | AK14: =SUM(AG14:AJ14) -> -78486 | AL14: -21317 | AM14: -21290 | AN14: -27130 | AO14: -26358 | AP14: =SUM(AL14:AO14) -> -96095 | AQ14: -17792 | AR14: -22335 | AS14: -20410 | AT14: -21137 | AU14: =SUM(AQ14:AT14) -> -81674 | AV14: -17805 | AW14: -19866 | AX14: -18907 | AY14: ='P&L - Consolidado'!O7 -> -19572 | AZ14: =SUM(AV14:AY14) -> -76150 | BA14: ='P&L - Consolidado'!M7 -> -20413 | BB14: ='P&L - Consolidado'!L7 -> -26065 | BC14: ='P&L - Consolidado'!J7 -> -21768 | BD14: ='P&L - Consolidado'!H7 -> -13183 | BE14: =SUM(BA14:BD14) -> -81429 | BF14: ='P&L - Consolidado'!F7 -> -21707 | BG14: ='P&L - Consolidado'!E7 -> -15375
A15: Gerais e Administrativas | B15: General and administrative | C15: -73640 | D15: -68051 | E15: -83208 | F15: -92659 | G15: =SUM(C15:F15) -> -317558 | H15: -92375 | I15: -91879 | J15: -86842 | K15: -97130 | L15: =SUM(H15:K15) -> -368226 | M15: -90648 | N15: -96244 | O15: -84723 | P15: -112791 | Q15: =SUM(M15:P15) -> -384406 | R15: -116383 | S15: -124074 | T15: -122830 | U15: -113825 | V15: =SUM(R15:U15) -> -477112 | W15: -123681 | X15: -119701 | Y15: -116338 | Z15: -123248 | AA15: =SUM(W15:Z15) -> -482968 | AB15: -113418 | AC15: -116217 | AD15: -120736 | AE15: -137350 | AF15: =SUM(AB15:AE15) -> -487721 | AG15: -156545 | AH15: -163153 | AI15: -153481 | AJ15: -172788 | AK15: =SUM(AG15:AJ15) -> -645967 | AL15: -142631 | AM15: -155940 | AN15: -150993 | AO15: -177959 | AP15: =SUM(AL15:AO15) -> -627523 | AQ15: -161089 | AR15: -166485 | AS15: -159265 | AT15: -171319 | AU15: =SUM(AQ15:AT15) -> -658158 | AV15: -155018 | AW15: -165615 | AX15: -168635 | AY15: ='P&L - Consolidado'!O9 -> -209265 | AZ15: =SUM(AV15:AY15) -> -698533 | BA15: ='P&L - Consolidado'!M9 -> -197143 | BB15: ='P&L - Consolidado'!L9 -> -208892 | BC15: ='P&L - Consolidado'!J9 -> -181161 | BD15: ='P&L - Consolidado'!H9 -> -206177 | BE15: =SUM(BA15:BD15) -> -793373 | BF15: ='P&L - Consolidado'!F9 -> -179874 | BG15: ='P&L - Consolidado'!E9 -> -189447
A16: Honorários da Administração | B16: Management fees | C16: -3372 | D16: -2827 | E16: -2706 | F16: -2719 | G16: =SUM(C16:F16) -> -11624 | H16: -5973 | I16: -2920 | J16: -4031 | K16: -3223 | L16: =SUM(H16:K16) -> -16147 | M16: -3511 | N16: -2892 | O16: -2467 | P16: -5532 | Q16: =SUM(M16:P16) -> -14402 | R16: -2878 | S16: -3511 | T16: -2806 | U16: -7921 | V16: =SUM(R16:U16) -> -17116 | W16: -3420 | X16: -4315 | Y16: -3104 | Z16: -8247 | AA16: =SUM(W16:Z16) -> -19086 | AB16: -3580 | AC16: -2569 | AD16: -2627 | AE16: -5334 | AF16: =SUM(AB16:AE16) -> -14110 | AG16: -2917 | AH16: -3526 | AI16: -2436 | AJ16: -7497 | AK16: =SUM(AG16:AJ16) -> -16376 | AL16: -4907 | AM16: -4383 | AN16: -3950 | AO16: -5731 | AP16: =SUM(AL16:AO16) -> -18971 | AQ16: -5978 | AR16: -4078 | AS16: -3595 | AT16: -4096 | AU16: =SUM(AQ16:AT16) -> -17747 | AV16: -5574 | AW16: -5740 | AX16: -5132 | AY16: ='P&L - Consolidado'!O10 -> -7406 | AZ16: =SUM(AV16:AY16) -> -23852 | BA16: ='P&L - Consolidado'!M10 -> -8545 | BB16: ='P&L - Consolidado'!L10 -> -9063 | BC16: ='P&L - Consolidado'!J10 -> -7301 | BD16: ='P&L - Consolidado'!H10 -> -5256 | BE16: =SUM(BA16:BD16) -> -30165 | BF16: ='P&L - Consolidado'!F10 -> -8738 | BG16: ='P&L - Consolidado'!E10 -> -9018
A17: Outras Despesas/Receitas | B17: Other | C17: -8778 | D17: -16015 | E17: -1526 | F17: -2013 | G17: =SUM(C17:F17) -> -28332 | H17: 66515 | I17: -15027 | J17: 24746 | K17: -4597 | L17: =SUM(H17:K17) -> 71637 | M17: -1866 | N17: -12181 | O17: -45808 | P17: -17645 | Q17: =SUM(M17:P17) -> -77500 | R17: -21965 | S17: -1545 | T17: -12436 | U17: 3207 | V17: =SUM(R17:U17) -> -32739 | W17: -5841 | X17: 1988 | Y17: 50859 | Z17: 23765 | AA17: =SUM(W17:Z17) -> 70771 | AB17: 25764 | AC17: -61064 | AD17: -49618 | AE17: -103516 | AF17: =SUM(AB17:AE17) -> -188434 | AG17: -5692 | AH17: 202057 | AI17: 26522 | AJ17: 61425 | AK17: =SUM(AG17:AJ17) -> 284312 | AL17: -26918 | AM17: 54834 | AN17: 78853 | AO17: 42417 | AP17: =SUM(AL17:AO17) -> 149186 | AQ17: 3676 | AR17: 10486 | AS17: 12574 | AT17: -9199 | AU17: =SUM(AQ17:AT17) -> 17537 | AV17: -5657 | AW17: -25158 | AX17: 14429 | AY17: ='P&L - Consolidado'!O12 -> -7745 | AZ17: =SUM(AV17:AY17) -> -24131 | BA17: ='P&L - Consolidado'!M12 -> -6068 | BB17: ='P&L - Consolidado'!L12 -> -2517 | BC17: ='P&L - Consolidado'!J12 -> -39348 | BD17: ='P&L - Consolidado'!H12 -> -6677 | BE17: =SUM(BA17:BD17) -> -54610 | BF17: ='P&L - Consolidado'!F12 -> -13934 | BG17: =SUM('P&L - Consolidado'!E12:E13) -> 2576
C18: =SUM(C14:C17) -> -117019 | D18: =SUM(D14:D17) -> -122288 | E18: =SUM(E14:E17) -> -127029 | F18: =SUM(F14:F17) -> -146738 | G18: =SUM(G14:G17) -> -513074 | H18: =SUM(H14:H17) -> -70578 | I18: =SUM(I14:I17) -> -146420 | J18: =SUM(J14:J17) -> -106152 | ... AA18: =SUM(AA14:AA17) -> -485061 | AB18: -104492 | AC18: =SUM(AC14:AC17) -> -193429 | AD18: =SUM(AD14:AD17) -> -184735 | AE18: =SUM(AE14:AE17) -> -269421 | AF18: =SUM(AF14:AF17) -> -752077 | AG18: -187566 | AH18: =SUM(AH14:AH17) -> 22921 | AI18: =SUM(AI14:AI17) -> -148495 | AJ18: =SUM(AJ14:AJ17) -> -143377 | AK18: =SUM(AK14:AK17) -> -456517 | AL18: =SUM(AL14:AL17) -> -195773 | AM18: =SUM(AM14:AM17) -> -126779 | AN18: =SUM(AN14:AN17) -> -103220 | AO18: =SUM(AO14:AO17) -> -167631 | ... AV18: =SUM(AV14:AV17) -> -184054 | AW18: -216379 | AX18: =SUM(AX14:AX17) -> -178245 | AY18: =SUM(AY14:AY17) -> -243988 | AZ18: =SUM(AV18:AY18) -> -822666 | BA18: =SUM(BA14:BA17) -> -232169 | BB18: =SUM(BB14:BB17) -> -246537 | BC18: =SUM(BC14:BC17) -> -249578 | BD18: =SUM(BD14:BD17) -> -231293 | BE18: =SUM(BA18:BD18) -> -959577 | BF18: =SUM(BF14:BF17) -> -224253 | BG18: =SUM(BG14:BG17) -> -211264
A19: Resultado de Equivalência Patrimonial | B19: Equity Income | C19: -556 | D19: 75528 | E19: 484 | F19: -4808 | G19: =SUM(C19:F19) -> 70648 | H19: -2929 | I19: -8714 | J19: -14059 | K19: -3097 | L19: =SUM(H19:K19) -> -28799 | M19: 4844 | N19: -23749 | O19: 1019 | P19: -2071 | Q19: =SUM(M19:P19) -> -19957 | R19: 2599 | S19: -8288 | T19: -4416 | U19: -4352 | V19: =SUM(R19:U19) -> -14457 | W19: -7728 | X19: -3753 | Y19: -9917 | Z19: -2504 | AA19: =SUM(W19:Z19) -> -23902 | AB19: 5632 | AC19: -2269 | AD19: 539 | AE19: -1859 | AF19: =SUM(AB19:AE19) -> 2043 | AG19: 931 | AH19: 10652 | AI19: 7568 | AJ19: 14728 | AK19: =SUM(AG19:AJ19) -> 33879 | AL19: 4674 | AM19: 6024 | AN19: 9760.5821 | AO19: 9986 | AP19: =SUM(AL19:AO19) -> 30444.582 | AQ19: 5857 | AR19: 3309 | AS19: 6410 | AT19: -1203 | AU19: =SUM(AQ19:AT19) -> 14373 | AV19: 815 | AW19: 6256 | AX19: 7072 | AY19: ='P&L - Consolidado'!O14 -> 8126 | AZ19: =SUM(AV19:AY19) -> 22269 | BA19: ='P&L - Consolidado'!M14 -> 5466 | BB19: ='P&L - Consolidado'!L14 -> 18776 | BC19: ='P&L - Consolidado'!J14 -> 11175 | BD19: ='P&L - Consolidado'!H14 -> 15302 | BE19: =SUM(BA19:BD19) -> 50719 | BF19: ='P&L - Consolidado'!F14 -> 1538 | BG19: ='P&L - Consolidado'!E14 -> 9434
A20: Lucro (Prejuízo) Operacional (EBIT) | B20: Operating Income (EBIT) | C20: =C18+C19+C11 -> 72907.773 | D20: =D18+D19+D11 -> 171545.08 | E20: =E18+E19+E11 -> 124889.1 | F20: =F18+F19+F11 -> 80260.165 | G20: =SUM(C20:F20) -> 449602.13 | H20: =H18+H19+H11 -> 153075.07 | I20: =I18+I19+I11 -> 101123 | J20: =J18+J19+J11 -> 114176.25 | K20: =K18+K19+K11 -> 110947.61 | L20: =SUM(H20:K20) -> 479321.94 | M20: =M18+M19+M11 -> 116046.1 | N20: =N18+N19+N11 -> 120859.28 | O20: =O18+O19+O11 -> 143985.58 | P20: =P18+P19+P11 -> 115664.72 | Q20: =SUM(M20:P20) -> 496555.68 | R20: =R18+R19+R11 -> 147127.89 | S20: =S18+S19+S11 -> 189991.45 | T20: =T18+T19+T11 -> 219722.1 | U20: =U18+U19+U11 -> 144651.02 | V20: =SUM(R20:U20) -> 701492.46 | W20: =W18+W19+W11 -> 143765.43 | X20: =X18+X19+X11 -> 201652.05 | Y20: =Y18+Y19+Y11 -> 226737.28 | Z20: =Z18+Z19+Z11 -> 104099.2 | AA20: =SUM(W20:Z20) -> 676253.97 | AB20: 85496.298 | AC20: =AC18+AC19+AC11 -> -332034.3 | AD20: =AD18+AD19+AD11 -> 71479.354 | AE20: =AE18+AE19+AE11 -> -9662 | AF20: =SUM(AB20:AE20) -> -184720.65 | AG20: 223081 | AH20: =AH18+AH19+AH11 -> 454290.52 | AI20: =AI18+AI19+AI11 -> 354663.7 | AJ20: =AJ18+AJ19+AJ11 -> 249449 | AK20: =SUM(AG20:AJ20) -> 1281484.2 | AL20: =AL18+AL19+AL11 -> 419901.02 | AM20: =AM18+AM19+AM11 -> 413895.23 | AN20: =AN18+AN19+AN11 -> 245496.72 | AO20: =AO18+AO19+AO11 -> 166390.51 | AP20: =SUM(AL20:AO20) -> 1245683.5 | AQ20: =AQ18+AQ19+AQ11 -> 165760.1 | AR20: =AR18+AR19+AR11 -> 245625.07 | AS20: =AS18+AS19+AS11 -> 197905.08 | AT20: =AT18+AT19+AT11 -> 173285.27 | AU20: =SUM(AQ20:AT20) -> 782575.52 | AV20: =AV18+AV19+AV11 -> 200889.76 | AW20: 266433 | AX20: =AX11+AX18+AX19 -> 306564 | AY20: =AY11+AY18+AY19 -> 247149 | AZ20: =SUM(AV20:AY20) -> 1021035.8 | BA20: =BA18+BA19+BA11 -> 217029 | BB20: =BB18+BB19+BB11 -> 306856 | BC20: =BC18+BC19+BC11 -> 221912 | BD20: =BD18+BD19+BD11 -> 196117 | BE20: =SUM(BA20:BD20) -> 941914 | BF20: =BF18+BF19+BF11 -> 218823 | BG20: =BG18+BG19+BG11 -> 283713
C21: =C20/C5 -> 0.046872879 | D21: =D20/D5 -> 0.10302668 | E21: =E20/E5 -> 0.069758273 | F21: =F20/F5 -> 0.043722961 | G21: =G20/G5 -> 0.065669321 | H21: =H20/H5 -> 0.085883508 | I21: =I20/I5 -> 0.05745209 | J21: =J20/J5 -> 0.071560951 | ... AA21: =AA20/AA5 -> 0.067514706 | AB21: 0.038432903 | AC21: =AC20/AC5 -> -0.28334343 | AD21: =AD20/AD5 -> 0.028423972 | AE21: =AE20/AE5 -> -0.0033908798 | AF21: =AF20/AF5 -> -0.021085465 | AG21: 0.071201457 | AH21: =AH20/AH5 -> 0.14268445 | AI21: =AI20/AI5 -> 0.098958112 | AJ21: =AJ20/AJ5 -> 0.065862687 | AK21: =AK20/AK5 -> 0.093618491 | AL21: =AL20/AL5 -> 0.098172146 | AM21: =AM20/AM5 -> 0.098725506 | AN21: =AN20/AN5 -> 0.056849803 | AO21: =AO20/AO5 -> 0.039998151 | ... AV21: =AV20/AV5 -> 0.055868418 | AW21: 0.069301154 | AX21: =AX20/AX5 -> 0.076980233 | AY21: =AY20/AY5 -> 0.063223919 | AZ21: =AZ20/AZ5 -> 0.066595892 | BA21: =BA20/BA5 -> 0.055110778 | BB21: =BB20/BB5 -> 0.074715946 | BC21: =BC20/BC5 -> 0.05836105 | BD21: =BD20/BD5 -> 0.055728989 | BE21: =BE20/BE5 -> 0.061296439 | ... BG21: =BG20/BG5 -> 0.070707818
A22: Resultado Financeiro | B22: Financial Results
A23: Receitas Financeiras | B23: Financial Revenue | C23: 14056 | D23: 5419 | E23: 8532 | F23: 9243 | G23: =SUM(C23:F23) -> 37250 | H23: 7051 | I23: 36526 | J23: 5984 | K23: 8276 | L23: =SUM(H23:K23) -> 57837 | M23: 7159 | N23: 16276 | O23: 8884 | P23: 22841 | Q23: =SUM(M23:P23) -> 55160 | R23: 4767 | S23: 8750 | T23: -2463 | U23: 3784 | V23: =SUM(R23:U23) -> 14838 | W23: 5792 | X23: 4680 | Y23: 30214 | Z23: 24658 | AA23: =SUM(W23:Z23) -> 65344 | AB23: 3421 | AC23: 7185 | AD23: 4346 | AE23: 18414 | AF23: =SUM(AB23:AE23) -> 33366 | AG23: 4640 | AH23: 67079 | AI23: 9307 | AJ23: 16827 | AK23: =SUM(AG23:AJ23) -> 97853 | AL23: 14402 | AM23: 24572 | AN23: 35162 | AO23: 40319 | AP23: =SUM(AL23:AO23) -> 114455 | AQ23: 49720 | AR23: 54793 | AS23: 50098 | AT23: 61540 | AU23: =SUM(AQ23:AT23) -> 216151 | AV23: 72201 | AW23: 44738 | AX23: 54759 | AY23: ='P&L - Consolidado'!O17 -> 252694 | AZ23: =SUM(AV23:AY23) -> 424392 | BA23: ='P&L - Consolidado'!M17 -> 34229 | BB23: ='P&L - Consolidado'!L17 -> 34225 | BC23: ='P&L - Consolidado'!J17 -> 33630 | BD23: ='P&L - Consolidado'!H17 -> 771438 | BE23: =SUM(BA23:BD23) -> 873522 | BF23: ='P&L - Consolidado'!F17 -> 28818 | BG23: ='P&L - Consolidado'!E17 -> 30357
A24: Despesas Financeiras | B24: Financial Expenses | C24: -73169 | D24: -90804 | E24: -93212 | F24: -97169 | G24: =SUM(C24:F24) -> -354354 | H24: -90135 | I24: -111061 | J24: -82632 | K24: -98425 | L24: =SUM(H24:K24) -> -382253 | M24: -73125 | N24: -64987 | O24: -159716 | P24: -96796 | Q24: =SUM(M24:P24) -> -394624 | R24: -66092 | S24: -70317 | T24: -49105 | U24: -53900 | V24: =SUM(R24:U24) -> -239414 | W24: -79180 | X24: -51480 | Y24: -54550 | Z24: -44914 | AA24: =SUM(W24:Z24) -> -230124 | AB24: -49399 | AC24: -75746 | AD24: -66936 | AE24: -70350 | AF24: =SUM(AB24:AE24) -> -262431 | AG24: -67805 | AH24: -124670 | AI24: -88614 | AJ24: -108327 | AK24: =SUM(AG24:AJ24) -> -389416 | AL24: -126473 | AM24: -141675 | AN24: -170613 | AO24: -274592 | AP24: =SUM(AL24:AO24) -> -713353 | AQ24: -177074 | AR24: -156962 | AS24: -174649 | AT24: -193674 | AU24: =SUM(AQ24:AT24) -> -702359 | AV24: -164427 | AW24: -159714 | AX24: -147954 | AY24: ='P&L - Consolidado'!O21 -> -169194 | AZ24: =SUM(AV24:AY24) -> -641289 | BA24: ='P&L - Consolidado'!M21 -> -168261 | BB24: ='P&L - Consolidado'!L21 -> -159902 | BC24: ='P&L - Consolidado'!J21 -> -165639 | BD24: ='P&L - Consolidado'!H21 -> -166630 | BE24: =SUM(BA24:BD24) -> -660432 | BF24: ='P&L - Consolidado'!F21 -> -155326 | BG24: ='P&L - Consolidado'!E21 -> -154863
A25: Variação cambial líquida | B25: Foreing exchange gains (losses) | C25: 8007 | D25: -4262 | E25: -12711 | F25: 9310 | G25: =SUM(C25:F25) -> 344 | H25: -14304 | I25: -6403 | J25: -9304 | K25: 9937 | L25: =SUM(H25:K25) -> -20074 | M25: -2513 | N25: -331 | O25: 1909 | P25: -6809 | Q25: =SUM(M25:P25) -> -7744 | R25: -3282 | S25: -3280 | T25: 2419 | U25: 7900 | V25: =SUM(R25:U25) -> 3757 | W25: -4414 | X25: -2904 | Y25: 231 | Z25: 1963 | AA25: =SUM(W25:Z25) -> -5124 | AB25: -3602 | AC25: -15560 | AD25: 20350 | AE25: -5109 | AF25: =SUM(AB25:AE25) -> -3921 | AG25: 4123 | AH25: -10952 | AI25: 551 | AJ25: -26776 | AK25: =SUM(AG25:AJ25) -> -33054 | AL25: -10181 | AM25: 4737 | AN25: -2326 | AO25: -10996 | AP25: =SUM(AL25:AO25) -> -18766 | AQ25: -4535 | AR25: -20239 | AS25: 5621 | AT25: -12515 | AU25: =SUM(AQ25:AT25) -> -31668 | AV25: -2930 | AW25: -1502 | AX25: -5991 | AY25: ='P&L - Consolidado'!O22 -> -208253 | AZ25: =SUM(AV25:AY25) -> -218676 | BA25: ='P&L - Consolidado'!M22 -> -5959 | BB25: ='P&L - Consolidado'!L22 -> -25694 | BC25: ='P&L - Consolidado'!J22 -> -12557 | BD25: ='P&L - Consolidado'!H22 -> -747155 | BE25: =SUM(BA25:BD25) -> -791365 | BF25: ='P&L - Consolidado'!F22 -> -19773 | BG25: ='P&L - Consolidado'!E22 -> 7464
C26: =SUM(C23:C25) -> -51106 | D26: =SUM(D23:D25) -> -89647 | E26: =SUM(E23:E25) -> -97391 | F26: =SUM(F23:F25) -> -78616 | G26: =SUM(G23:G25) -> -316760 | H26: =SUM(H23:H25) -> -97388 | I26: =SUM(I23:I25) -> -80938 | J26: =SUM(J23:J25) -> -85952 | ... AA26: =SUM(AA23:AA25) -> -169904 | AB26: -49580 | AC26: =SUM(AC23:AC25) -> -84121 | AD26: =SUM(AD23:AD25) -> -42240 | AE26: =SUM(AE23:AE25) -> -57045 | AF26: =SUM(AF23:AF25) -> -232986 | AG26: -59042 | AH26: =SUM(AH23:AH25) -> -68543 | AI26: =SUM(AI23:AI25) -> -78756 | AJ26: =SUM(AJ23:AJ25) -> -118276 | AK26: =SUM(AK23:AK25) -> -324617 | AL26: =SUM(AL23:AL25) -> -122252 | AM26: =SUM(AM23:AM25) -> -112366 | AN26: =SUM(AN23:AN25) -> -137777 | AO26: =SUM(AO23:AO25) -> -245269 | ... AV26: =SUM(AV23:AV25) -> -95156 | AW26: -116478 | AX26: =SUM(AX23:AX25) -> -99186 | AY26: =SUM(AY23:AY25) -> -124753 | AZ26: =SUM(AV26:AY26) -> -435573 | BA26: =SUM(BA23:BA25) -> -139991 | BB26: =SUM(BB23:BB25) -> -151371 | BC26: =SUM(BC23:BC25) -> -144566 | BD26: =SUM(BD23:BD25) -> -142347 | BE26: =SUM(BA26:BD26) -> -578275 | BF26: =SUM(BF23:BF25) -> -146281 | BG26: =SUM(BG23:BG25) -> -117042
A27: Lucro (Prejuízo) antes do Imp. de Renda e da CS | B27: Earnings After Financial Results | C27: =C20+C26 -> 21801.773 | D27: =D20+D26 -> 81898.084 | E27: =E20+E26 -> 27498.103 | F27: =F20+F26 -> 1644.1653 | G27: =SUM(C27:F27) -> 132842.13 | H27: =H20+H26 -> 55687.071 | I27: =I20+I26 -> 20185.001 | J27: =J20+J26 -> 28224.251 | K27: =K20+K26 -> 30735.611 | L27: =SUM(H27:K27) -> 134831.94 | M27: =M20+M26 -> 47567.098 | N27: =N20+N26 -> 71817.284 | O27: =O20+O26 -> -4937.4214 | P27: =P20+P26 -> 34900.725 | Q27: =SUM(M27:P27) -> 149347.68 | R27: =R20+R26 -> 82520.889 | S27: =S20+S26 -> 125144.45 | T27: =T20+T26 -> 170573.1 | U27: =U20+U26 -> 102435.02 | V27: =SUM(R27:U27) -> 480673.46 | W27: =W20+W26 -> 65963.433 | X27: =X20+X26 -> 151948.05 | Y27: =Y20+Y26 -> 202632.28 | Z27: =Z20+Z26 -> 85806.203 | AA27: =SUM(W27:Z27) -> 506349.97 | AB27: 35916.298 | AC27: =AC20+AC26 -> -416155.3 | AD27: =AD20+AD26 -> 29239.354 | AE27: =AE20+AE26 -> -66707 | AF27: =SUM(AB27:AE27) -> -417706.65 | AG27: 164039 | AH27: =AH20+AH26 -> 385747.52 | AI27: =AI20+AI26 -> 275907.7 | AJ27: =AJ20+AJ26 -> 131173 | AK27: =SUM(AG27:AJ27) -> 956867.21 | AL27: =AL20+AL26 -> 297649.02 | AM27: =AM20+AM26 -> 301529.23 | AN27: =AN20+AN26 -> 107719.72 | AO27: =AO20+AO26 -> -78878.49 | AP27: =SUM(AL27:AO27) -> 628019.48 | AQ27: =AQ20+AQ26 -> 33871.097 | AR27: =AR20+AR26 -> 123217.07 | AS27: =AS20+AS26 -> 78975.078 | AT27: =AT20+AT26 -> 28636.274 | AU27: =SUM(AQ27:AT27) -> 264699.52 | AV27: =AV20+AV26 -> 105733.76 | AW27: 149955 | AX27: =AX20+AX26 -> 207378 | AY27: =AY20+AY26 -> 122396 | AZ27: =SUM(AV27:AY27) -> 585462.76 | BA27: =BA20+BA26 -> 77038 | BB27: =BB20+BB26 -> 155485 | BC27: =BC20+BC26 -> 77346 | BD27: =BD20+BD26 -> 53770 | BE27: =SUM(BA27:BD27) -> 363639 | BF27: =BF20+BF26 -> 72542 | BG27: =BG20+BG26 -> 166671
C28: =C27/C5 -> 0.014016501 | D28: =D27/D5 -> 0.049186416 | E28: =E27/E5 -> 0.015359388 | F28: =F27/F5 -> 0.00089568437 | G28: =G27/G5 -> 0.019403049 | H28: =H27/H5 -> 0.0312435 | I28: =I27/I5 -> 0.01146792 | J28: =J27/J5 -> 0.017689793 | ... AA28: =AA27/AA5 -> 0.050552117 | AB28: 0.016145349 | AC28: =AC27/AC5 -> -0.35512858 | AD28: =AD27/AD5 -> 0.011627114 | AE28: =AE27/AE5 -> -0.023410828 | AF28: =AF27/AF5 -> -0.047680315 | AG28: 0.052356838 | AH28: =AH27/AH5 -> 0.12115633 | AI28: =AI27/AI5 -> 0.076983647 | AJ28: =AJ27/AJ5 -> 0.034633958 | AK28: =AK27/AK5 -> 0.069903682 | AL28: =AL27/AL5 -> 0.069589836 | AM28: =AM27/AM5 -> 0.071923095 | AN28: =AN27/AN5 -> 0.024944712 | AO28: =AO27/AO5 -> -0.018961381 | ... AV28: =AV27/AV5 -> 0.029405072 | AW28: 0.039004382 | AX28: =AX27/AX5 -> 0.052073977 | AY28: =AY27/AY5 -> 0.031310484 | AZ28: =AZ27/AZ5 -> 0.03818614 | BA28: =BA27/BA5 -> 0.019562474 | BB28: =BB27/BB5 -> 0.037858829 | BC28: =BC27/BC5 -> 0.020341369 | BD28: =BD27/BD5 -> 0.015279388 | BE28: =BE27/BE5 -> 0.023664343 | ... BG28: =BG27/BG5 -> 0.041538254
A29: Imp. de Renda / Contrib. Social | B29: Income Taxes | C29: -12099.447 | D29: 1746.2678 | E29: -14932.497 | F29: 12292.3 | G29: =SUM(C29:F29) -> -12993.377 | H29: -32944 | I29: -5983.1559 | J29: -9933.8441 | K29: 3159 | L29: =SUM(H29:K29) -> -45702 | M29: -34646.521 | N29: -32522.366 | O29: -4448 | P29: 2478 | Q29: =SUM(M29:P29) -> -69138.886 | R29: -74940 | S29: -60029 | T29: -58279 | U29: 18716 | V29: =SUM(R29:U29) -> -174532 | W29: 15089 | X29: -21886 | Y29: -55824 | Z29: -22315 | AA29: =SUM(W29:Z29) -> -84936 | AB29: -5590 | AC29: 64469 | AD29: -34932 | AE29: -26154 | AF29: =SUM(AB29:AE29) -> -2207 | AG29: -86037 | AH29: -150726 | AI29: -71865 | AJ29: -21302 | AK29: =SUM(AG29:AJ29) -> -329930 | AL29: -108937 | AM29: -82338 | AN29: -18131 | AO29: -14442 | AP29: =SUM(AL29:AO29) -> -223848 | AQ29: -33469 | AR29: -41112 | AS29: -72542 | AT29: -11686 | AU29: =SUM(AQ29:AT29) -> -158809 | AV29: -23910 | AW29: -78459 | AX29: -77798 | AY29: ='P&L - Consolidado'!O24 -> -25212 | AZ29: =SUM(AV29:AY29) -> -205379 | BA29: ='P&L - Consolidado'!M24 -> -41506 | BB29: ='P&L - Consolidado'!L24 -> -45152 | BC29: ='P&L - Consolidado'!J24 -> -3850 | BD29: ='P&L - Consolidado'!H24 -> -55996 | BE29: =SUM(BA29:BD29) -> -146504 | BF29: ='P&L - Consolidado'!F24 -> -35437 | BG29: ='P&L - Consolidado'!E24 -> -43399
A30: Participação de Não Controladores | B30: Minority Shareholders | C30: -16380.681 | D30: -13403.283 | E30: -10131.915 | F30: -30567.121 | G30: =SUM(C30:F30) -> -70483 | H30: -15761 | I30: -21394.133 | J30: -13397.867 | K30: -17047 | L30: =SUM(H30:K30) -> -67600 | M30: -14170.89 | N30: -14724.602 | O30: -19336 | P30: -25574 | Q30: =SUM(M30:P30) -> -73805.492 | R30: -20547 | S30: -20981 | T30: -18815 | U30: -44474 | V30: =SUM(R30:U30) -> -104817 | W30: -17956 | X30: -19672 | Y30: -21970 | Z30: -24382 | AA30: =SUM(W30:Z30) -> -83980 | AB30: -21176 | AC30: -667 | AD30: -13184 | AE30: -36839 | AF30: =SUM(AB30:AE30) -> -71866 | AG30: -26500 | AH30: -20235 | AI30: -27027 | AJ30: -15955 | AK30: =SUM(AG30:AJ30) -> -89717 | AL30: -28506 | AM30: -28706 | AN30: -20201 | AO30: -47826 | AP30: =SUM(AL30:AO30) -> -125239 | AQ30: -16743 | AR30: -22745 | AS30: -11218 | AT30: -24452 | AU30: =SUM(AQ30:AT30) -> -75158 | AV30: -31567 | AW30: -34571 | AX30: -20408 | AY30: -28818 | AZ30: =SUM(AV30:AY30) -> -115364 | BA30: -24640 | BB30: =-'P&L - Consolidado'!L33 -> -23510 | BC30: =-'P&L - Consolidado'!J33 -> -38429 | BD30: =-'P&L - Consolidado'!H33 -> -32172 | BE30: =SUM(BA30:BD30) -> -118751 | BF30: =-'P&L - Consolidado'!F33 -> -33185 | BG30: =-'P&L - Consolidado'!E33 -> -36403
A32: Lucro Líquido (Prejuízo) | B32: Net Income (Loss) | C32: =C27+C29+C30 -> -6678.3554 | D32: =D27+D29+D30 -> 70241.068 | E32: =E27+E29+E30 -> 2433.691 | F32: =F27+F29+F30 -> -16630.655 | G32: =SUM(C32:F32) -> 49365.749 | H32: =H27+H29+H30 -> 6982.0714 | I32: =I27+I29+I30 -> -7192.2873 | J32: =J27+J29+J30 -> 4892.54 | K32: =K27+K29+K30 -> 16847.611 | L32: =SUM(H32:K32) -> 21529.935 | M32: =M27+M29+M30 -> -1250.3134 | N32: =N27+N29+N30 -> 24570.316 | O32: =O27+O29+O30 -> -28721.421 | P32: =P27+P29+P30 -> 11804.725 | Q32: =SUM(M32:P32) -> 6403.3058 | R32: =R27+R29+R30 -> -12966.111 | S32: =S27+S29+S30 -> 44134.451 | T32: =T27+T29+T30 -> 93479.1 | U32: =U27+U29+U30 -> 76677.02 | V32: =SUM(R32:U32) -> 201324.46 | W32: =W27+W29+W30 -> 63096.433 | X32: =X27+X29+X30 -> 110390.05 | Y32: =Y27+Y29+Y30 -> 124838.28 | Z32: =Z27+Z29+Z30 -> 39109.203 | AA32: =SUM(W32:Z32) -> 337433.97 | AB32: 9150.2979 | AC32: =AC27+AC29+AC30 -> -352353.3 | AD32: =AD27+AD29+AD30 -> -18876.646 | AE32: =AE27+AE29+AE30 -> -129700 | AF32: =SUM(AB32:AE32) -> -491779.65 | AG32: 51502 | AH32: =AH27+AH29+AH30 -> 214786.52 | AI32: =AI27+AI29+AI30 -> 177015.7 | AJ32: =AJ27+AJ29+AJ30 -> 93916 | AK32: =SUM(AG32:AJ32) -> 537220.21 | AL32: =AL27+AL29+AL30 -> 160206.02 | AM32: =AM27+AM29+AM30 -> 190485.23 | AN32: =AN27+AN29+AN30 -> 69387.722 | AO32: =AO27+AO29+AO30 -> -141146.49 | AP32: =SUM(AL32:AO32) -> 278932.48 | AQ32: =AQ27+AQ29+AQ30 -> -16340.903 | AR32: =AR27+AR29+AR30 -> 59360.073 | AS32: =AS27+AS29+AS30 -> -4784.9222 | AT32: =AT27+AT29+AT30 -> -7501.7261 | AU32: =SUM(AQ32:AT32) -> 30732.522 | AV32: =AV27+AV29+AV30 -> 50256.757 | AW32: 36925 | AX32: =AX27+AX29+AX30 -> 109172 | AY32: =AY27+AY29+AY30 -> 68366 | AZ32: =SUM(AV32:AY32) -> 264719.76 | BA32: =BA27+BA29+BA30 -> 10892 | BB32: =BB27+BB29+BB30 -> 86823 | BC32: =BC27+BC29+BC30 -> 35067 | BD32: =BD27+BD29+BD30 -> -34398 | BE32: =BE27+BE29+BE30 -> 98384 | BF32: =BF27+BF29+BF30 -> 3920 | BG32: =BG27+BG29+BG30 -> 86869
C33: =C32/C5 -> -0.0042935579 | D33: =D32/D5 -> 0.042185436 | E33: =E32/E5 -> 0.0013593666 | F33: =F32/F5 -> -0.0090598056 | G33: =G32/G5 -> 0.007210409 | H33: =H32/H5 -> 0.0039173249 | I33: =I32/I5 -> -0.004086231 | J33: =J32/J5 -> 0.0030664417 | ... AA33: =AA32/AA5 -> 0.033688165 | AB33: 0.0041133069 | AC33: =AC32/AC5 -> -0.30068277 | AD33: =AD32/AD5 -> -0.0075063529 | AE33: =AE32/AE5 -> -0.045518227 | AF33: =AF32/AF5 -> -0.056135589 | AG33: 0.016438054 | AH33: =AH32/AH5 -> 0.067460568 | AI33: =AI32/AI5 -> 0.049390844 | AJ33: =AJ32/AJ5 -> 0.024796893 | AK33: =AK32/AK5 -> 0.039246481 | AL33: =AL32/AL5 -> 0.037455896 | AM33: =AM32/AM5 -> 0.045436017 | AN33: =AN32/AN5 -> 0.016068151 | AO33: =AO32/AO5 -> -0.033929812 | ... AV33: =AV32/AV5 -> 0.013976648 | AW33: 0.0096044601 | AX33: =AX32/AX5 -> 0.027413806 | AY33: =AY32/AY5 -> 0.017488909 | AZ33: =AZ32/AZ5 -> 0.017266044 | BA33: =BA32/BA5 -> 0.0027658359 | BB33: =BB32/BB5 -> 0.021140413 | BC33: =BC32/BC5 -> 0.0092223357 | BD33: =BD32/BD5 -> -0.0097746027 | BE33: =BE32/BE5 -> 0.0064024835 | ... BG33: =BG32/BG5 -> 0.021649757
A34: EBITDA | B34: EBITDA | C34: 139833.52 | D34: 242501.9 | E34: 204669.95 | F34: 164061.6 | G34: =SUM(C34:F34) -> 751066.97 | H34: 236295.42 | I34: 179570.95 | J34: 191109.14 | K34: 189249.51 | L34: =SUM(H34:K34) -> 796225.02 | M34: 185393.84 | N34: 194139.02 | O34: 220254.57 | P34: 198765.91 | Q34: =SUM(M34:P34) -> 798553.34 | R34: 227112.85 | S34: 275408.5 | T34: 311999.73 | U34: 242554.66 | V34: =SUM(R34:U34) -> 1057075.7 | W34: 242587.39 | X34: 304247.27 | Y34: 333779.69 | Z34: 215195.55 | AA34: =SUM(W34:Z34) -> 1095809.9 | AB34: 204967.46 | AC34: -199515.39 | AD34: 207676.01 | AE34: 159011.44 | AF34: =SUM(AB34:AE34) -> 372139.51 | AG34: 367938.26 | AH34: 592729.23 | AI34: 489861.86 | AJ34: 390803.28 | AK34: =SUM(AG34:AJ34) -> 1841332.6 | AL34: 548151.67 | AM34: 534572.73 | AN34: 362701.61 | AO34: 291488.72 | AP34: =SUM(AL34:AO34) -> 1736914.7 | AQ34: 286760.45 | AR34: 363406.6 | AS34: 313322.08 | AT34: 289375.03 | AU34: =SUM(AQ34:AT34) -> 1252864.2 | AV34: 316641.76 | AW34: 388931 | AX34: 440235 | AY34: 378263 | AZ34: =SUM(AV34:AY34) -> 1524070.8 | BA34: 354362.01 | BB34: 450478.87 | BC34: ='Indicadores | KPI'!BD6 -> 360435 | BD34: ='Indicadores | KPI'!BE6 -> 328178 | BE34: =SUM(BA34:BD34) -> 1493453.9 | BF34: ='Indicadores | KPI'!BG6 -> 357046 | BG34: ='Indicadores | KPI'!BH6 -> 417527
C35: =C34/C5 -> 0.089899878 | D35: =D34/D5 -> 0.14564198 | E35: =E34/E5 -> 0.1143208 | F35: =F34/F5 -> 0.089375081 | G35: =G34/G5 -> 0.10970157 | H35: =H34/H5 -> 0.13257468 | I35: =I34/I5 -> 0.10202156 | J35: =J34/J5 -> 0.1197793 | ... AA35: =AA34/AA5 -> 0.10940163 | AB35: 0.092138425 | AC35: =AC34/AC5 -> -0.17025764 | AD35: =AD34/AD5 -> 0.082582965 | AE35: =AE34/AE5 -> 0.055805079 | AF35: =AF34/AF5 -> 0.042478925 | AG35: 0.117436 | AH35: =AH34/AH5 -> 0.18616555 | AI35: =AI34/AI5 -> 0.13668105 | AJ35: =AJ34/AJ5 -> 0.10318484 | AK35: =AK34/AK5 -> 0.13451807 | AL35: =AL34/AL5 -> 0.12815693 | AM35: =AM34/AM5 -> 0.12751044 | AN35: =AN34/AN5 -> 0.083991 | AO35: =AO34/AO5 -> 0.070070162 | ... AV35: =AV34/AV5 -> 0.088059612 | AW35: 0.10116377 | AX35: =AX34/AX5 -> 0.1105459 | AY35: =AY34/AY5 -> 0.09676458 | AZ35: =AZ34/AZ5 -> 0.099405775 | BA35: =BA34/BA5 -> 0.089984132 | BB35: =BB34/BB5 -> 0.10968648 | BC35: =BC34/BC5 -> 0.094791472 | BD35: =BD34/BD5 -> 0.0932557 | BE35: =BE34/BE5 -> 0.097188708 | ... BG35: =BG34/BG5 -> 0.10405735

Sheet Receita - Revenue
A1: Consolidado | B1: Consolidated
C2: 1Q15 | D2: 2Q15 | E2: 3Q15 | F2: 4Q15 | G2: 2015 | H2: 1Q16 | I2: 2Q16 | J2: 3Q16 | K2: 4Q16 | L2: 2016 | M2: 1Q17 | N2: 2Q17 | O2: 3Q17 | P2: 4Q17 | Q2: 2017 | R2: 1Q18 | S2: 2Q18 | T2: 3Q18 | U2: 4Q18 | V2: 2018 | W2: 1Q19 | X2: 2Q19 | Y2: 3Q19 | Z2: 4Q19 | AA2: 2019 | AB2: 1Q20 | AC2: 2Q20 | AD2: 3Q20 | AE2: 4Q20 | AF2: 2020 | AG2: 1Q21 | AH2: 2Q21 | AI2: 3Q21 | AJ2: 4Q21 | AK2: 2021 | AL2: 1Q22 | AM2: 2Q22 | AN2: 3Q22 | AO2: 4Q22 | AP2: 2022 | AQ2: 1Q23 | AR2: 2Q23 | AS2: 3Q23 | AT2: 4Q23 | AU2: 2023 | AV2: 1Q24 | AW2: 2Q24 | AX2: 3Q24 | AY2: 4Q24 | AZ2: 2024 | BA2: 1Q25 | BB2: 2Q25 | BC2: 3Q25 | BD2: 4Q25 | BE2: 2025 | BF2: 1Q26 | BG2: 2Q26
A3: Receita Operacional Líquida - R$ mil | B3: Net Operating Revenue- R$ thousand | C3: 1T15 | D3: 2T15 | E3: 3T15 | F3: 4T15 | G3: 2015 | H3: 1T16 | I3: 2T16 | J3: 3T16 | K3: 4T16 | L3: 2016 | M3: 1T17 | N3: 2T17 | O3: 3T17 | P3: 4T17 | Q3: 2017 | R3: 1T18 | S3: 2T18 | T3: 3T18 | U3: 4T18 | V3: 2018 | W3: 1T19 | X3: 2T19 | Y3: 3T19 | Z3: 4T19 | AA3: 2019 | AB3: 1T20 | AC3: 2T20 | AD3: 3T20 | AE3: 4T20 | AF3: 2020 | AG3: 1T21 | AH3: 2T21 | AI3: 3T21 | AJ3: 4T21 | AK3: 2021 | AL3: 1T22 | AM3: 2T22 | AN3: 3T22 | AO3: 4T22 | AP3: 2022 | AQ3: 1T23 | AR3: 2T23 | AS3: 3T23 | AT3: 4T23 | AU3: 2023 | AV3: 1T24 | AW3: 2T24 | AX3: 3T24 | AY3: 4T24 | AZ3: 2024 | BA3: 1T25 | BB3: 2T25 | BC3: 3T25 | BD3: 4T25 | BE3: 2025 | BF3: 1T26 | BG3: 2T26
A4: Rodas Alumínio (Veículos Leves) | B4: Aluminum Wheels (Light vehicles) | C4: 55826.718 | D4: 51406.334 | E4: 45925.259 | F4: 45857.582 | G4: 199015.89 | H4: 64556.254 | I4: 77321.594 | J4: 86827.66 | K4: 83670.502 | L4: 312376.01 | M4: 95863.583 | N4: 96598.923 | O4: 103304.59 | P4: 99676.893 | Q4: 395443.99 | R4: 124153.39 | S4: 131893.76 | T4: 128774.13 | U4: 115297.1 | V4: 500118.37 | W4: 128353.3 | X4: 128200.67 | Y4: 132201.9 | Z4: 98378.282 | AA4: 487134.15 | AB4: 83410.737 | AC4: 16630.592 | AD4: 85530.498 | AE4: 108157.48 | AF4: 293729.31 | AG4: 113754.44 | AH4: 127555.91 | AI4: 146455.94 | AJ4: 126539.64 | AK4: =SUM(AG4:AJ4) -> 514305.92 | AL4: 127475.65 | AM4: 142561.86 | AN4: 185289.02 | AO4: 145037.5 | AP4: =SUM(AL4:AO4) -> 600364.03 | AQ4: 163406.36 | AR4: 168729.99 | AS4: 175382.85 | AT4: 160190.46 | AU4: =SUM(AQ4:AT4) -> 667709.66 | AV4: 163394.69 | AW4: 182932.1 | AX4: 222634.44 | AY4: 214167.85 | AZ4: =SUM(AV4:AY4) -> 783129.08 | BA4: 226790.48 | BB4: 262871 | BC4: 263219 | BD4: 221455 | BE4: =SUM(BA4:BD4) -> 974335.48 | BF4: 241468 | BG4: 295494
A5: Rodas Aço (Veículos Leves) | B5: Steel Wheels (Light vehicles) | C5: 86091.388 | D5: 77419.531 | E5: 75153.514 | F5: 65774.839 | G5: 304439.27 | H5: 59818.323 | I5: 62127.665 | J5: 69106.489 | K5: 77518.81 | L5: 268571.29 | M5: 80416.907 | N5: 93925.839 | O5: 99338.179 | P5: 102702.66 | Q5: 376383.59 | R5: 99069.386 | S5: 105517.08 | T5: 110520.82 | U5: 97538.081 | V5: 412645.36 | W5: 106924.05 | X5: 127513.61 | Y5: 129235.29 | Z5: 99418.607 | AA5: 463091.56 | AB5: 92178.857 | AC5: 19156.332 | AD5: 93941.46 | AE5: 93076.701 | AF5: 298353.35 | AG5: 94939.348 | AH5: 112655.05 | AI5: 104828.07 | AJ5: 114536.84 | AK5: =SUM(AG5:AJ5) -> 426959.31 | AL5: 127454.01 | AM5: 150685.7 | AN5: 176694.32 | AO5: 135961.37 | AP5: =SUM(AL5:AO5) -> 590795.39 | AQ5: 136872.3 | AR5: 150553.86 | AS5: 161730.19 | AT5: 131773.19 | AU5: =SUM(AQ5:AT5) -> 580929.55 | AV5: 132047.02 | AW5: 136812.83 | AX5: 164831.33 | AY5: 146000.07 | AZ5: =SUM(AV5:AY5) -> 579691.25 | BA5: 132684.03 | BB5: 145772 | BC5: 181207 | BD5: 147606 | BE5: =SUM(BA5:BD5) -> 607269.03 | BF5: 149936 | BG5: 166699
A6: Rodas Aço (Veículos Comerciais) | B6: Steel Wheels (Commercial vehicles) | C6: 95298.834 | D6: 79696.223 | E6: 78127.409 | F6: 46507.35 | G6: 299629.82 | H6: 61136.574 | I6: 72734.943 | J6: 84326.806 | K6: 76884.65 | L6: 295082.97 | M6: 82579.905 | N6: 107693.61 | O6: 119111.54 | P6: 93763.767 | Q6: 403148.83 | R6: 127748.15 | S6: 134414.59 | T6: 158953.39 | U6: 145584.45 | V6: 566700.57 | W6: 153568 | X6: 174301.93 | Y6: 181888.91 | Z6: 140410.61 | AA6: 650169.45 | AB6: 126965.31 | AC6: 75193.895 | AD6: 168498.38 | AE6: 183865.6 | AF6: 554523.18 | AG6: 242798.07 | AH6: 275929.33 | AI6: 370919.39 | AJ6: 361028.53 | AK6: =SUM(AG6:AJ6) -> 1250675.3 | AL6: 394994.83 | AM6: 399312.15 | AN6: 420374.53 | AO6: 355379.32 | AP6: =SUM(AL6:AO6) -> 1570060.8 | AQ6: 288711.05 | AR6: 263324.2 | AS6: 255887.05 | AT6: 217163.73 | AU6: =SUM(AQ6:AT6) -> 1025086 | AV6: 242314.76 | AW6: 267040.95 | AX6: 280967.81 | AY6: 236546.2 | AZ6: =SUM(AV6:AY6) -> 1026869.7 | BA6: 235906.04 | BB6: 253852 | BC6: 248267 | BD6: 144060 | BE6: =SUM(BA6:BD6) -> 882085.04 | BF6: 198324 | BG6: 207281
A7: Comp. Estruturais (Veículos Leves) | B7: Structural Components (Light vehicles) | C7: 40363.381 | D7: 34789.908 | E7: 37781.839 | F7: 39295.597 | G7: 152230.72 | H7: 36783.019 | I7: 33576.174 | J7: 31535.434 | K7: 40634.134 | L7: 142528.76 | M7: 38943.069 | N7: 40239.606 | O7: 42229.592 | P7: 44369.981 | Q7: 165782.25 | R7: 45447.796 | S7: 47932.099 | T7: 38424.19 | U7: 34089.412 | V7: 165893.5 | W7: 37994.363 | X7: 55877.182 | Y7: 47728.539 | Z7: 51413.113 | AA7: 193013.2 | AB7: 39538.184 | AC7: 14437.726 | AD7: 54943.615 | AE7: 58059.968 | AF7: 166979.49 | AG7: 64791.642 | AH7: 90402.496 | AI7: 111407.28 | AJ7: 75705.886 | AK7: =SUM(AG7:AJ7) -> 342307.3 | AL7: 101866.82 | AM7: 112573.03 | AN7: 127900.73 | AO7: 118183.36 | AP7: =SUM(AL7:AO7) -> 460523.95 | AQ7: 114473.51 | AR7: 115560.93 | AS7: 123975.95 | AT7: 113081.21 | AU7: =SUM(AQ7:AT7) -> 467091.59 | AV7: 102806.91 | AW7: 114782.3 | AX7: 124815.21 | AY7: 125568.69 | AZ7: =SUM(AV7:AY7) -> 467973.11 | BA7: 114125.01 | BB7: 127840 | BC7: 134215 | BD7: 130597 | BE7: =SUM(BA7:BD7) -> 506777.01 | BF7: 119229 | BG7: 121304
A8: Comp. Estruturais (Veículos Comerciais) | B8: Structural Components (Commercial vehicles) | C8: 127634.44 | D8: 110636.92 | E8: 86980.481 | F8: 70049.061 | G8: 395300.9 | H8: 87087.919 | I8: 100373.89 | J8: 96446.381 | K8: 97788.664 | L8: 381696.86 | M8: 97232.561 | N8: 118669.37 | O8: 136190.94 | P8: 138473.89 | Q8: 490566.75 | R8: 161369.2 | S8: 159558.9 | T8: 190171.09 | U8: 212994.05 | V8: 724093.23 | W8: 177666.73 | X8: 254171.68 | Y8: 231663.79 | Z8: 224006 | AA8: 887508.2 | AB8: 172629.47 | AC8: 52179.132 | AD8: 178119.39 | AE8: 218552.48 | AF8: 621480.47 | AG8: 268303 | AH8: 328999.85 | AI8: 431475.43 | AJ8: 419685.76 | AK8: =SUM(AG8:AJ8) -> 1448464 | AL8: 443102.8 | AM8: 467558.07 | AN8: 527852.76 | AO8: 506447.07 | AP8: =SUM(AL8:AO8) -> 1944960.7 | AQ8: 322144.64 | AR8: 308928.59 | AS8: 296337.21 | AT8: 279039.06 | AU8: =SUM(AQ8:AT8) -> 1206449.5 | AV8: 335321.59 | AW8: 367842.02 | AX8: 407291.27 | AY8: 392927.61 | AZ8: =SUM(AV8:AY8) -> 1503382.5 | BA8: 331454.69 | BB8: 405024 | BC8: 404903 | BD8: 287366 | BE8: =SUM(BA8:BD8) -> 1428747.7 | BF8: 329078 | BG8: 349236
A9: América do Sul | B9: South America | C9: =SUM(C4:C8) -> 405214.76 | D9: =SUM(D4:D8) -> 353948.91 | E9: =SUM(E4:E8) -> 323968.5 | F9: =SUM(F4:F8) -> 267484.43 | G9: =SUM(G4:G8) -> 1350616.6 | H9: =SUM(H4:H8) -> 309382.09 | I9: =SUM(I4:I8) -> 346134.27 | J9: =SUM(J4:J8) -> 368242.77 | ... AU9: =SUM(AU4:AU8) -> 3947266.3 | AV9: =SUM(AV4:AV8)+1 -> 975885.97 | AW9: =SUM(AW4:AW8) -> 1069410.2 | AX9: =SUM(AX4:AX8)-1 -> 1200539.1 | AY9: =SUM(AY4:AY8) -> 1115210.4 | AZ9: =SUM(AV9:AY9) -> 4361045.6 | BA9: =SUM(BA4:BA8) -> 1040960.2 | BB9: =SUM(BB4:BB8) -> 1195359 | BC9: =SUM(BC4:BC8) -> 1231811 | BD9: =SUM(BD4:BD8) -> 931084 | BE9: =SUM(BE4:BE8) -> 4399214.2 | BF9: =SUM(BF4:BF8) -> 1038035 | BG9: =SUM(BG4:BG8) -> 1140014
C10: =C9/C$27 -> 0.26051519 | D10: =D9/D$27 -> 0.21257492 | E10: =E9/E$27 -> 0.18095642 | F10: =F9/F$27 -> 0.14571628 | G10: =G9/G$27 -> 0.19727238 | H10: =H9/H$27 -> 0.17358029 | I10: =I9/I$27 -> 0.19665298 | J10: =J9/J$27 -> 0.2307994 | ... BG10: =BG9/BG$27 -> 0.28411776
A11: Rodas Alumínio (Veículos Leves) | B11: Aluminum Wheels (Light vehicles) | C11: 53275.1 | D11: 63877.322 | E11: 82085.679 | F11: 83012.251 | G11: 282250.35 | H11: 86654.425 | I11: 72616.156 | J11: 67056.831 | K11: 65454.116 | L11: 291781.53 | M11: 68516.393 | N11: 72898.644 | O11: 57623.205 | P11: 61361.504 | Q11: 260399.75 | R11: 62973.433 | S11: 81461.696 | T11: 114428.03 | U11: 103342.65 | V11: 362205.81 | W11: 111241.08 | X11: 119366.2 | Y11: 109273.06 | Z11: 96133.624 | AA11: 436013.97 | AB11: 101482.63 | AC11: 41140.64 | AD11: 117717 | AE11: 120970.98 | AF11: 381311.24 | AG11: 129983.69 | AH11: 103211.49 | AI11: 128707.25 | AJ11: 156471.69 | AK11: =SUM(AG11:AJ11) -> 518374.13 | AL11: 148343.43 | AM11: 143272.89 | AN11: 143074.17 | AO11: 117387.86 | AP11: =SUM(AL11:AO11) -> 552078.35 | AQ11: 161443.34 | AR11: 158063.15 | AS11: 159105.48 | AT11: 155776.73 | AU11: =SUM(AQ11:AT11) -> 634388.7 | AV11: 155580.92 | AW11: 162880.51 | AX11: 179724.61 | AY11: 166325.52 | AZ11: =SUM(AV11:AX11) -> 498186.03 | BA11: 155636.23 | BB11: 147141 | BC11: 145961 | BD11: 129678 | BE11: =SUM(BA11:BD11) -> 578416.23 | BF11: 201616 | BG11: 193933
A12: Rodas Aço (Veículos Leves) | B12: Steel Wheels (Light vehicles) | C12: 244123 | D12: 260693.21 | E12: 294548.31 | F12: 299216.05 | G12: 1098580.6 | H12: 291770.43 | I12: 272197.77 | J12: 252003.82 | K12: 262169.23 | L12: 1078141.2 | M12: 248823.73 | N12: 262123.37 | O12: 245239.5 | P12: 238714.54 | Q12: 994901.14 | R12: 246005.45 | S12: 280931.49 | T12: 323004.35 | U12: 313664.76 | V12: 1163606.1 | W12: 276063.8 | X12: 277832.01 | Y12: 289028.31 | Z12: 250178.21 | AA12: 1093102.3 | AB12: 254896.64 | AC12: 100027.78 | AD12: 340541.09 | AE12: 346120.77 | AF12: 1041586.3 | AG12: 369418.66 | AH12: 305202.28 | AI12: 407144.36 | AJ12: 461827.7 | AK12: =SUM(AG12:AJ12) -> 1543593 | AL12: 503922.51 | AM12: 472172.43 | AN12: 411485.75 | AO12: 371550.91 | AP12: =SUM(AL12:AO12) -> 1759131.6 | AQ12: 351310.91 | AR12: 361344.85 | AS12: 414048.25 | AT12: 332993.36 | AU12: =SUM(AQ12:AT12) -> 1459697.4 | AV12: 348859.57 | AW12: 445102.02 | AX12: 420112.73 | AY12: 377114.95 | AZ12: =SUM(AV12:AX12) -> 1214074.3 | BA12: 386922.32 | BB12: 455338 | BC12: 444008 | BD12: 383787 | BE12: =SUM(BA12:BD12) -> 1670055.3 | BF12: 362125 | BG12: 397656
A13: Rodas Aço (Veículos Comerciais) | B13: Steel Wheels (Commercial vehicles) | C13: 54757.897 | D13: 70142.725 | E13: 78374.825 | F13: 63410.083 | G13: 266685.53 | H13: 69068.161 | I13: 62434.891 | J13: 52766.802 | K13: 57591.806 | L13: 241861.66 | M13: 53180.707 | N13: 60510.454 | O13: 55112.663 | P13: 52423.354 | Q13: 221227.18 | R13: 64059.766 | S13: 81495.956 | T13: 99096.902 | U13: 92088.438 | V13: 336741.06 | W13: 96754.317 | X13: 105344.67 | Y13: 104080.19 | Z13: 78235.225 | AA13: 384414.4 | AB13: 78320.672 | AC13: 64523.784 | AD13: 86864.93 | AE13: 79960.791 | AF13: 309670.18 | AG13: 91487.891 | AH13: 98214.066 | AI13: 99802.771 | AJ13: 106363.45 | AK13: =SUM(AG13:AJ13) -> 395868.18 | AL13: 117452.6 | AM13: 120117.39 | AN13: 125619.58 | AO13: 90704.863 | AP13: =SUM(AL13:AO13) -> 453894.43 | AQ13: 95520.24 | AR13: 90849.811 | AS13: 91533.286 | AT13: 78466.728 | AU13: =SUM(AQ13:AT13) -> 356370.06 | AV13: 88311.189 | AW13: 98481.629 | AX13: 95178.626 | AY13: 72332.593 | AZ13: =SUM(AV13:AX13) -> 281971.44 | BA13: 104175.74 | BB13: 104795 | BC13: 101486 | BD13: 73068 | BE13: =SUM(BA13:BD13) -> 383524.74 | BF13: 79240 | BG13: 101080
A14: Comp. Estruturais (Veículos Comerciais) | B14: Structural Components (Commercial vehicles) | C14: 147943.92 | D14: 174442.39 | E14: 183499.4 | F14: 192858.05 | G14: 698743.75 | H14: 164011.53 | I14: 135064.12 | J14: 113935.66 | K14: 119573.6 | L14: 532584.9 | M14: 138093.56 | N14: 171087.77 | O14: 180757.8 | P14: 160617.13 | Q14: 650556.27 | R14: 188842.89 | S14: 229640.73 | T14: 309280.17 | U14: 221734.46 | V14: 949498.25 | W14: 293325.19 | X14: 322880.5 | Y14: 299885.63 | Z14: 213185.03 | AA14: 1129276.3 | AB14: 233162 | AC14: 138438.39 | AD14: 252292.99 | AE14: 245558.89 | AF14: 869452.27 | AG14: 278553 | AH14: 337755.91 | AI14: 429152.38 | AJ14: 418602.53 | AK14: =SUM(AG14:AJ14) -> 1464063.8 | AL14: 561996.04 | AM14: 537796.04 | AN14: 561455.28 | AO14: 572083.59 | AP14: =SUM(AL14:AO14) -> 2233330.9 | AQ14: 538166.77 | AR14: 446993.65 | AS14: 446152.62 | AT14: 436593.96 | AU14: =SUM(AQ14:AT14) -> 1867907 | AV14: 469229.18 | AW14: 494976.05 | AX14: 544900.72 | AY14: 464603.89 | AZ14: =SUM(AV14:AX14) -> 1509105.9 | BA14: 423778.31 | BB14: 336349 | BC14: 238695 | BD14: 245874 | BE14: =SUM(BA14:BD14) -> 1244696.3 | BF14: 307665 | BG14: 345139
A15: América do Norte | B15: North America | C15: =SUM(C11:C14) -> 500099.91 | D15: =SUM(D11:D14) -> 569155.64 | E15: =SUM(E11:E14) -> 638508.22 | F15: =SUM(F11:F14) -> 638496.44 | G15: =SUM(G11:G14) -> 2346260.2 | H15: =SUM(H11:H14) -> 611504.54 | I15: =SUM(I11:I14) -> 542312.94 | J15: =SUM(J11:J14) -> 485763.11 | ... AU15: =SUM(AU11:AU14) -> 4318363.1 | AV15: =SUM(AV11:AV14)-1 -> 1061979.8 | AW15: =SUM(AW11:AW14) -> 1201440.2 | AX15: =SUM(AX11:AX14)+1 -> 1239917.7 | AY15: =SUM(AY11:AY14) -> 1080376.9 | AZ15: =SUM(AV15:AX15) -> 3503337.7 | BA15: =SUM(BA11:BA14) -> 1070512.6 | BB15: =SUM(BB11:BB14) -> 1043623 | BC15: =SUM(BC11:BC14) -> 930150 | BD15: =SUM(BD11:BD14) -> 832407 | BE15: =SUM(BE11:BE14) -> 3876692.6 | BF15: =SUM(BF11:BF14) -> 950646 | BG15: =SUM(BG11:BG14) -> 1037808
C16: =C15/C$27 -> 0.32151747 | D16: =D15/D$27 -> 0.34182394 | E16: =E15/E$27 -> 0.35664628 | F16: =F15/F$27 -> 0.34783081 | G16: =G15/G$27 -> 0.34269705 | H16: =H15/H$27 -> 0.34308753 | I16: =I15/I$27 -> 0.30811008 | J16: =J15/J$27 -> 0.3044563 | ... BG16: =BG15/BG$27 -> 0.25864567
A17: Rodas Alumínio (Veículos Leves) | B17: Aluminum Wheels (Light vehicles) | C17: 248710.2 | D17: 290526.22 | E17: 325938.01 | F17: 351251.34 | G17: 1216425.8 | H17: 338233.24 | I17: 343067.95 | J17: 291502.2 | K17: 345182.32 | L17: 1317985.7 | M17: 330407.16 | N17: 352205.15 | O17: 355061.05 | P17: 396406.67 | Q17: 1434080 | R17: 421216.15 | S17: 460483.01 | T17: 457984.14 | U17: 443699.03 | V17: 1783382.3 | W17: 445823.69 | X17: 441063.97 | Y17: 416771.87 | Z17: 462199.42 | AA17: 1765858.9 | AB17: 434454.6 | AC17: 249798.48 | AD17: 460201.06 | AE17: 534808.51 | AF17: 1679262.7 | AG17: 533486.93 | AH17: 516146.04 | AI17: 420969.3 | AJ17: 510036.95 | AK17: =SUM(AG17:AJ17) -> 1980639.2 | AL17: 562153.44 | AM17: 593709.48 | AN17: 597017.63 | AO17: 683953.29 | AP17: =SUM(AL17:AO17) -> 2436833.8 | AQ17: 682080.45 | AR17: 675394.72 | AS17: 562619.25 | AT17: 539782.76 | AU17: =SUM(AQ17:AT17) -> 2459877.2 | AV17: 581580.62 | AW17: 594550.64 | AX17: 591961.89 | AY17: 688796.04 | AZ17: =SUM(AV17:AX17) -> 1768093.1 | BA17: 734965.85 | BB17: 765300 | BC17: 673711 | BD17: 706370 | BE17: =SUM(BA17:BD17) -> 2880346.8 | BF17: 744105 | BG17: 752470
A18: Rodas Aço (Veículos Leves) | B18: Steel Wheels (Light vehicles) | C18: 156523.93 | D18: 177654.29 | E18: 208356.77 | F18: 266499.9 | G18: 809034.9 | H18: 213272.37 | I18: 214409.02 | J18: 186290.9 | K18: 200232.69 | L18: 814204.98 | M18: 179351.05 | N18: 199811.88 | O18: 210343.91 | P18: 221962.7 | Q18: 811469.53 | R18: 218079.24 | S18: 255283.16 | T18: 239059.93 | U18: 245998.97 | V18: 958421.31 | W18: 220617.17 | X18: 243228.14 | Y18: 225416.17 | Z18: 236500.6 | AA18: 925762.08 | AB18: 229434.01 | AC18: 186327.57 | AD18: 256661.76 | AE18: 313960.33 | AF18: 986383.67 | AG18: 288002.18 | AH18: 263464.52 | AI18: 287498.37 | AJ18: 310681.5 | AK18: =SUM(AG18:AJ18) -> 1149646.6 | AL18: 329746.47 | AM18: 334589.57 | AN18: 299896.2 | AO18: 308267.24 | AP18: =SUM(AL18:AO18) -> 1272499.5 | AQ18: 330487.6 | AR18: 321817.06 | AS18: 305693.5 | AT18: 356817.26 | AU18: =SUM(AQ18:AT18) -> 1314815.4 | AV18: 355103.84 | AW18: 351441.66 | AX18: 307973.07 | AY18: 361149.36 | AZ18: =SUM(AV18:AX18) -> 1014518.6 | BA18: 387433.3 | BB18: 377226 | BC18: 348437 | BD18: 361147 | BE18: =SUM(BA18:BD18) -> 1474243.3 | BF18: 360281 | BG18: 339662
